<?xml version="1.0" ?>
<!-- =================================================================================== -->
<!-- |    This document was autogenerated by xacro from /home/kan5r/catkin_ws/src/cybergear_one_leg_description/urdf/cybergear_one_leg.xacro | -->
<!-- |    EDITING THIS FILE BY HAND IS NOT RECOMMENDED                                 | -->
<!-- =================================================================================== -->
<robot name="cybergear_one_leg">
  <material name="silver">
    <color rgba="0.700 0.700 0.700 1.000"/>
  </material>
  <transmission name="joint_hy_tran">
    <type>transmission_interface/SimpleTransmission</type>
    <joint name="joint_hy">
      <hardwareInterface>hardware_interface/EffortJointInterface</hardwareInterface>
    </joint>
    <actuator name="joint_hy_actr">
      <hardwareInterface>hardware_interface/EffortJointInterface</hardwareInterface>
      <mechanicalReduction>1</mechanicalReduction>
    </actuator>
  </transmission>
  <transmission name="joint_knee_tran">
    <type>transmission_interface/SimpleTransmission</type>
    <joint name="joint_knee">
      <hardwareInterface>hardware_interface/EffortJointInterface</hardwareInterface>
    </joint>
    <actuator name="joint_knee_actr">
      <hardwareInterface>hardware_interface/EffortJointInterface</hardwareInterface>
      <mechanicalReduction>1</mechanicalReduction>
    </actuator>
  </transmission>
  <gazebo>
    <plugin filename="libgazebo_ros_control.so" name="control"/>
  </gazebo>
  <gazebo reference="hip">
    <material>Gazebo/Silver</material>
    <mu1>0.2</mu1>
    <mu2>0.2</mu2>
    <selfCollide>true</selfCollide>
    <gravity>true</gravity>
  </gazebo>
  <gazebo reference="uleg">
    <material>Gazebo/Silver</material>
    <mu1>0.2</mu1>
    <mu2>0.2</mu2>
    <selfCollide>true</selfCollide>
  </gazebo>
  <gazebo reference="lleg">
    <material>Gazebo/Silver</material>
    <mu1>0.2</mu1>
    <mu2>0.2</mu2>
    <selfCollide>true</selfCollide>
  </gazebo>
  <link name="hip">
    <inertial>
      <origin rpy="0 0 0" xyz="0.0002819920937144005 0.015839426830908936 1.1514529854865785e-05"/>
      <mass value="0.31861004240365326"/>
      <inertia ixx="0.000126" ixy="0.0" ixz="0.0" iyy="0.000213" iyz="0.0" izz="0.00013"/>
    </inertial>
    <visual>
      <origin rpy="0 0 0" xyz="0 0 0"/>
      <geometry>
        <mesh filename="package://cybergear_one_leg_description/meshes/hip.stl" scale="0.001 0.001 0.001"/>
      </geometry>
      <material name="silver"/>
    </visual>
    <collision>
      <origin rpy="0 0 0" xyz="0 0 0"/>
      <geometry>
        <mesh filename="package://cybergear_one_leg_description/meshes/hip.stl" scale="0.001 0.001 0.001"/>
      </geometry>
    </collision>
  </link>
  <link name="uleg">
    <inertial>
      <origin rpy="0 0 0" xyz="-0.010595257498656998 -0.033951385417500785 0.0012442950145930855"/>
      <mass value="0.4855306568273375"/>
      <inertia ixx="0.000326" ixy="-0.000108" ixz="2.9e-05" iyy="0.000864" iyz="1.2e-05" izz="0.000783"/>
    </inertial>
    <visual>
      <origin rpy="0 0 0" xyz="0.0 -0.0 0.0"/>
      <geometry>
        <mesh filename="package://cybergear_one_leg_description/meshes/uleg.stl" scale="0.001 0.001 0.001"/>
      </geometry>
      <material name="silver"/>
    </visual>
    <collision>
      <origin rpy="0 0 0" xyz="0.0 -0.0 0.0"/>
      <geometry>
        <mesh filename="package://cybergear_one_leg_description/meshes/uleg.stl" scale="0.001 0.001 0.001"/>
      </geometry>
    </collision>
  </link>
  <link name="lleg">
    <inertial>
      <origin rpy="0 0 0" xyz="0.029382679354009608 -0.006951791165447925 -0.09243709675891992"/>
      <mass value="0.097550817276456"/>
      <inertia ixx="0.000328" ixy="-0.0" ixz="7.8e-05" iyy="0.000357" iyz="0.0" izz="3.6e-05"/>
    </inertial>
    <visual>
      <origin rpy="0 0 0" xyz="0.15 0.048 0.000261"/>
      <geometry>
        <mesh filename="package://cybergear_one_leg_description/meshes/lleg.stl" scale="0.001 0.001 0.001"/>
      </geometry>
      <material name="silver"/>
    </visual>
    <collision>
      <origin rpy="0 0 0" xyz="0.15 0.048 0.000261"/>
      <geometry>
        <mesh filename="package://cybergear_one_leg_description/meshes/lleg.stl" scale="0.001 0.001 0.001"/>
      </geometry>
    </collision>
  </link>
  <joint name="joint_hy" type="continuous">
    <origin rpy="0 0 0" xyz="0.0 0.0 0.0"/>
    <parent link="hip"/>
    <child link="uleg"/>
    <axis xyz="0.0 -1.0 -0.0"/>
  </joint>
  <joint name="joint_knee" type="revolute">
    <origin rpy="0 0 0" xyz="-0.15 -0.048 -0.000261"/>
    <parent link="uleg"/>
    <child link="lleg"/>
    <axis xyz="0.0 -1.0 0.0"/>
    <limit effort="100" lower="-1.745329" upper="0.698132" velocity="100"/>
  </joint>
</robot>

